Workbook
Name Tiles: 'Accepted Drops'!$B$84:$B$328
Name AllPrices: 'Accepted Drops'!$AC$83:$AF$331
Name Boss: 'Ultimate Breakdown'!$A$39:$A$93
Name BossLookup: 'Ultimate Breakdown'!$A$39:$B$93
Name AllDrops: 'Accepted Drops'!$AG$83:$AQ$331
Name BossCode: 'Ultimate Breakdown'!$B$39:$B$93

Sheet Board
AJ10: ="Points Tally: " & AF53 -> Points Tally: 596
C13: =IF('Accepted Drops'!J3>='Accepted Drops'!L3,IMAGE("https://summerbingo.s.gy/angelCompleteLow",2),IMAGE("https://summerbingo.s.gy/angel" & 'Accepted Drops'!J3,2)) | H13: =IF('Accepted Drops'!T3>='Accepted Drops'!V3,IMAGE("https://summerbingo.s.gy/hueyCompleteLow",2),IMAGE("https://summerbingo.s.gy/huey" & 'Accepted Drops'!T3,2)) | M13: =IF('Accepted Drops'!AD3>='Accepted Drops'!AF3,IMAGE("https://summerbingo.s.gy/guardiansCompleteMed",2),IMAGE("https://summerbingo.s.gy/guardians" & 'Accepted Drops'!AD3,2)) | R13: =IF('Accepted Drops'!AN3>='Accepted Drops'!AP3,IMAGE("https://summerbingo.s.gy/tdsCompleteMed",2),IMAGE("https://summerbingo.s.gy/tds" & 'Accepted Drops'!AN3,2)) | W13: =IF('Accepted Drops'!AX3>='Accepted Drops'!AZ3,IMAGE("https://summerbingo.s.gy/cerbCompleteHigh",2),IMAGE("https://summerbingo.s.gy/cerb" & 'Accepted Drops'!AX3,2)) | AB13: =IF('Accepted Drops'!BH3>='Accepted Drops'!BJ3,IMAGE("https://summerbingo.s.gy/coxCompleteHigh",2),IMAGE("https://summerbingo.s.gy/cox" & 'Accepted Drops'!BH3,2))
AK16: RULESET AND POINTS
C18: =IF('Accepted Drops'!J9>='Accepted Drops'!L9,IMAGE("https://summerbingo.s.gy/bootsCompleteMed",2),IMAGE("https://summerbingo.s.gy/boots" & 'Accepted Drops'!J9,2)) | H18: =IF('Accepted Drops'!T10>='Accepted Drops'!V10,IMAGE("https://summerbingo.s.gy/yamaCompleteHigh",2),IMAGE("https://summerbingo.s.gy/yama" & 'Accepted Drops'!T10,2)) | M18: =IF('Accepted Drops'!AD13>='Accepted Drops'!AF13,IMAGE("https://summerbingo.s.gy/tempoCompleteLow",2),IMAGE("https://summerbingo.s.gy/tempo" & 'Accepted Drops'!AD13,2)) | R18: =IF('Accepted Drops'!AN8>='Accepted Drops'!AP8,IMAGE("https://summerbingo.s.gy/tobCompleteHigh",2),IMAGE("https://summerbingo.s.gy/tob" & 'Accepted Drops'!AN8,2)) | W18: =IF('Accepted Drops'!AX12>='Accepted Drops'!AZ12,IMAGE("https://summerbingo.s.gy/mortimerCompleteMed",2),IMAGE("https://summerbingo.s.gy/mortimer" & 'Accepted Drops'!AX12,2)) | AB18: =IF('Accepted Drops'!BH20>='Accepted Drops'!BJ20,IMAGE("https://summerbingo.s.gy/gorillasCompleteMed",2),IMAGE("https://summerbingo.s.gy/gorillas" & 'Accepted Drops'!BH20,2)) | AK18: 1. Easy Tiles (yellow) = 5 points 2. Medium Tiles (orange) = 10 points 3. Hard Tiles (red) = 20 points 4. 30 bonus points for a row or column completion. Please see 'Accepted Drops' tab for details on accepted uniques and how much they contribute towards tile completion (e.g. Araxxor tile requires 12 'points' to complete which can be 4 nally pieces and 1 araxyte head and 1 jar of venom). - If you go over the 'point' requirement to complete a tile, this does not award additional score. Tiles with a ✅ require pre-verification screenshots before submissions are accepted. Bonus Tiles: - These tiles exist in case there are any keen PvMers out there willing to flex their skills. Points are awarded per unique. - Receiving a jar / pet / megarare will contribute to the main tile completion and award bonus points. - Only 1 Chompy Chick, Beef, Skotos, Pet Chaos Elemental, Jar of Dirt, Jar of Light and Jar of Darkness will contribute bonus points per team. - Each bonus tile can award a maximum of 20 bonus points. Additional Notes: - DT2 vestige drops require additional screenshots of 2 sets of gold ring drops (i.e. 1x gold ring and 2x gold rings). - Mortimer is just the theme. Tasks can be from any slayer master. - Double pickpocket with Rogue's set does not contribute additional completions. - Buying fletching knife from Vale Totems shop will not count as a game notification will not be given.
C23: =IF('Accepted Drops'!J17>='Accepted Drops'!L17,IMAGE("https://summerbingo.s.gy/gwdCompleteHigh",2),IMAGE("https://summerbingo.s.gy/gwd" & 'Accepted Drops'!J17,2)) | H23: =IF('Accepted Drops'!T16>='Accepted Drops'!V16,IMAGE("https://summerbingo.s.gy/vorkathCompleteMed",2),IMAGE("https://summerbingo.s.gy/vorkath" & 'Accepted Drops'!T16,2)) | M23: =IF('Accepted Drops'!AD23>='Accepted Drops'!AF23,IMAGE("https://summerbingo.s.gy/toaCompleteHigh",2),IMAGE("https://summerbingo.s.gy/toa" & 'Accepted Drops'!AD23,2)) | R23: =IF('Accepted Drops'!AN21>='Accepted Drops'!AP21,IMAGE("https://summerbingo.s.gy/GOTRCompleteLow",2),IMAGE("https://summerbingo.s.gy/GOTR" & 'Accepted Drops'!AN21,2)) | W23: =IF('Accepted Drops'!AX39>='Accepted Drops'!AZ39,IMAGE("https://summerbingo.s.gy/muspahCompleteMed",2),IMAGE("https://summerbingo.s.gy/muspah" & 'Accepted Drops'!AX39,2)) | AB23: =IF('Accepted Drops'!BH29>='Accepted Drops'!BJ29,IMAGE("https://summerbingo.s.gy/titansCompleteLow",2),IMAGE("https://summerbingo.s.gy/titans" & 'Accepted Drops'!BH29,2))
C28: =IF('Accepted Drops'!J37>='Accepted Drops'!L37,IMAGE("https://summerbingo.s.gy/wtCompleteLow",2),IMAGE("https://summerbingo.s.gy/wt" & 'Accepted Drops'!J37,2)) | H28: =IF('Accepted Drops'!T25>='Accepted Drops'!V25,IMAGE("https://summerbingo.s.gy/araxxorCompleteHigh",2),IMAGE("https://summerbingo.s.gy/araxxor" & 'Accepted Drops'!T25,2)) | M28: =IF('Accepted Drops'!AD32>='Accepted Drops'!AF32,IMAGE("https://summerbingo.s.gy/zulrahCompleteMed",2),IMAGE("https://summerbingo.s.gy/zulrah" & 'Accepted Drops'!AD32,2)) | R28: =IF('Accepted Drops'!AN30>='Accepted Drops'!AP30,IMAGE("https://summerbingo.s.gy/zombiesCompleteLow",2),IMAGE("https://summerbingo.s.gy/zombies" & 'Accepted Drops'!AN30,2)) | W28: =IF('Accepted Drops'!AX44>='Accepted Drops'!AZ44,IMAGE("https://summerbingo.s.gy/doomCompleteHigh",2),IMAGE("https://summerbingo.s.gy/doom" & 'Accepted Drops'!AX44,2)) | AB28: =IF('Accepted Drops'!BH37>='Accepted Drops'!BJ37,IMAGE("https://summerbingo.s.gy/sireCompleteMed",2),IMAGE("https://summerbingo.s.gy/sire" & 'Accepted Drops'!BH37,2))
C33: =IF('Accepted Drops'!J43>='Accepted Drops'!L43,IMAGE("https://summerbingo.s.gy/hydraCompleteHigh",2),IMAGE("https://summerbingo.s.gy/hydra" & 'Accepted Drops'!J43,2)) | H33: =IF('Accepted Drops'!T33>='Accepted Drops'!V33,IMAGE("https://summerbingo.s.gy/zalcanoCompleteMed",2),IMAGE("https://summerbingo.s.gy/zalcano" & 'Accepted Drops'!T33,2)) | M33: =IF('Accepted Drops'!AD42>='Accepted Drops'!AF42,IMAGE("https://summerbingo.s.gy/scurriusCompleteLow",2),IMAGE("https://summerbingo.s.gy/scurrius" & 'Accepted Drops'!AD42,2)) | R33: =IF('Accepted Drops'!AN35>='Accepted Drops'!AP35,IMAGE("https://summerbingo.s.gy/gauntletCompleteMed",2),IMAGE("https://summerbingo.s.gy/gauntlet" & 'Accepted Drops'!AN35,2)) | W33: =IF('Accepted Drops'!AX52>='Accepted Drops'!AZ52,IMAGE("https://summerbingo.s.gy/toolsCompleteLow",2),IMAGE("https://summerbingo.s.gy/tools" & 'Accepted Drops'!AX52,2)) | AB33: =IF('Accepted Drops'!BH41>='Accepted Drops'!BJ41,IMAGE("https://summerbingo.s.gy/maggotCompleteHigh",2),IMAGE("https://summerbingo.s.gy/maggot" & 'Accepted Drops'!BH41,2))
C38: =IF('Accepted Drops'!J52>='Accepted Drops'!L52,IMAGE("https://summerbingo.s.gy/thievingCompleteMed",2),IMAGE("https://summerbingo.s.gy/thieving" & 'Accepted Drops'!J52,2)) | H38: =IF('Accepted Drops'!T40>='Accepted Drops'!V40,IMAGE("https://summerbingo.s.gy/barrowsCompleteLow",2),IMAGE("https://summerbingo.s.gy/barrows" & 'Accepted Drops'!T40,2)) | M38: =IF('Accepted Drops'!AD47>='Accepted Drops'!AF47,IMAGE("https://summerbingo.s.gy/dt2_CompleteHigh",2),IMAGE("https://summerbingo.s.gy/dt2_" & 'Accepted Drops'!AD47,2)) | R38: =IF('Accepted Drops'!AN42>='Accepted Drops'!AP42,IMAGE("https://summerbingo.s.gy/wildCompleteHigh",2),IMAGE("https://summerbingo.s.gy/wild" & 'Accepted Drops'!AN42,2)) | W38: =IF('Accepted Drops'!AX58>='Accepted Drops'!AZ58,IMAGE("https://summerbingo.s.gy/dksCompleteMed",2),IMAGE("https://summerbingo.s.gy/dks" & 'Accepted Drops'!AX58,2)) | AB38: =IF('Accepted Drops'!BH47>='Accepted Drops'!BJ47,IMAGE("https://summerbingo.s.gy/moonsCompleteLow",2),IMAGE("https://summerbingo.s.gy/moons" & 'Accepted Drops'!BH47,2))
C45: =IMAGE("https://summerbingo.s.gy/nex" & 'Accepted Drops'!AO69,2) | H45: =IMAGE("https://summerbingo.s.gy/pnm" & 'Accepted Drops'!AE69,2) | M45: =IMAGE("https://summerbingo.s.gy/mega" & 'Accepted Drops'!U69,2) | R45: =IMAGE("https://summerbingo.s.gy/jpet" & 'Accepted Drops'!K69,2) | W45: =IMAGE("https://summerbingo.s.gy/colo" & 'Accepted Drops'!BI69,2) | AB45: =IMAGE("https://summerbingo.s.gy/corp" & 'Accepted Drops'!AY69,2)
AF53: =SUM(C55,H55,M55,R55,W55,AB55,AG55,C60,H60,M60,R60,W60,AB60,AG60,C65,H65,M65,R65,W65,AB65,AG65,C70,H70,M70,R70,W70,AB70,AG70,C75,H75,M75,R75,W75,AB75,AG75,C80,H80,M80,R80,W80,AB80,AG80,C85,H85,M85,R85,W85,AB85,C87,H87,M87,R87,W87,AB87) -> 596
C55: =IF('Accepted Drops'!J3>='Accepted Drops'!L3, 5, "") -> 5 | H55: =IF('Accepted Drops'!T3>='Accepted Drops'!V3, 5, "") -> 5 | M55: =IF('Accepted Drops'!AD3>='Accepted Drops'!AF3, 10, "") -> 10 | R55: =IF('Accepted Drops'!AN3>='Accepted Drops'!AP3, 10, "") -> 10 | W55: =IF('Accepted Drops'!AX3>='Accepted Drops'!AZ3, 20, "") -> 20 | AB55: =IF('Accepted Drops'!BH3>='Accepted Drops'!BJ3, 20, "") -> 20 | AG55: =IF( (C55<>"") + (H55<>"") + (M55<>"") + (R55<>"") + (W55<>"") + (AB55<>"") = 6, 30, "" ) -> 30
C60: =IF('Accepted Drops'!J9>='Accepted Drops'!L9, 10, "") -> 10 | H60: =IF('Accepted Drops'!T10>='Accepted Drops'!V10, 20, "") | M60: =IF('Accepted Drops'!AD13>='Accepted Drops'!AF13, 5, "") -> 5 | R60: =IF('Accepted Drops'!AN8>='Accepted Drops'!AP8, 20, "") | W60: =IF('Accepted Drops'!AX12>='Accepted Drops'!AZ12, 10, "") -> 10 | AB60: =IF('Accepted Drops'!BH20>='Accepted Drops'!BJ20, 10, "") -> 10 | AG60: =IF( (C60<>"") + (H60<>"") + (M60<>"") + (R60<>"") + (W60<>"") + (AB60<>"") = 6, 30, "" )
C65: =IF('Accepted Drops'!J17>='Accepted Drops'!L17, 20, "") -> 20 | H65: =IF('Accepted Drops'!T16>='Accepted Drops'!V16, 10, "") -> 10 | M65: =IF('Accepted Drops'!AD23>='Accepted Drops'!AF23, 20, "") -> 20 | R65: =IF('Accepted Drops'!AN21>='Accepted Drops'!AP21, 5, "") -> 5 | W65: =IF('Accepted Drops'!AX39>='Accepted Drops'!AZ39, 10, "") -> 10 | AB65: =IF('Accepted Drops'!BH29>='Accepted Drops'!BJ29, 5, "") -> 5 | AG65: =IF( (C65<>"") + (H65<>"") + (M65<>"") + (R65<>"") + (W65<>"") + (AB65<>"") = 6, 30, "" ) -> 30
C70: =IF('Accepted Drops'!J37>='Accepted Drops'!L37, 5, "") -> 5 | H70: =IF('Accepted Drops'!T25>='Accepted Drops'!V25, 20, "") -> 20 | M70: =IF('Accepted Drops'!AD32>='Accepted Drops'!AF32, 10, "") -> 10 | R70: =IF('Accepted Drops'!AN30>='Accepted Drops'!AP30, 5, "") -> 5 | W70: =IF('Accepted Drops'!AX44>='Accepted Drops'!AZ44, 20, "") -> 20 | AB70: =IF('Accepted Drops'!BH37>='Accepted Drops'!BJ37, 10, "") -> 10 | AG70: =IF( (C70<>"") + (H70<>"") + (M70<>"") + (R70<>"") + (W70<>"") + (AB70<>"") = 6, 30, "" ) -> 30
C75: =IF('Accepted Drops'!J43>='Accepted Drops'!L43, 20, "") -> 20 | H75: =IF('Accepted Drops'!T33>='Accepted Drops'!V33, 10, "") -> 10 | M75: =IF('Accepted Drops'!AD42>='Accepted Drops'!AF42, 5, "") -> 5 | R75: =IF('Accepted Drops'!AN35>='Accepted Drops'!AP35, 10, "") -> 10 | W75: =IF('Accepted Drops'!AX52>='Accepted Drops'!AZ52, 5, "") -> 5 | AB75: =IF('Accepted Drops'!BH41>='Accepted Drops'!BJ41, 20, "") | AG75: =IF( (C75<>"") + (H75<>"") + (M75<>"") + (R75<>"") + (W75<>"") + (AB75<>"") = 6, 30, "" )
C80: =IF('Accepted Drops'!J52>='Accepted Drops'!L52, 10, "") -> 10 | H80: =IF('Accepted Drops'!T40>='Accepted Drops'!V40, 5, "") -> 5 | M80: =IF('Accepted Drops'!AD47>='Accepted Drops'!AF47, 20, "") -> 20 | R80: =IF('Accepted Drops'!AN42>='Accepted Drops'!AP42, 20, "") -> 20 | W80: =IF('Accepted Drops'!AX58>='Accepted Drops'!AZ58, 10, "") -> 10 | AB80: =IF('Accepted Drops'!BH47>='Accepted Drops'!BJ47, 5, "") -> 5 | AG80: =IF( (C80<>"") + (H80<>"") + (M80<>"") + (R80<>"") + (W80<>"") + (AB80<>"") = 6, 30, "" ) -> 30
C85: =IF( (C55<>"") + (C60<>"") + (C65<>"") + (C70<>"") + (C75<>"") + (C80<>"") = 6, 30, "" ) -> 30 | H85: =IF( (H55<>"") + (H60<>"") + (H65<>"") + (H70<>"") + (H75<>"") + (H80<>"") = 6, 30, "" ) | M85: =IF( (M55<>"") + (M60<>"") + (M65<>"") + (M70<>"") + (M75<>"") + (M80<>"") = 6, 30, "" ) -> 30 | R85: =IF( (R55<>"") + (R60<>"") + (R65<>"") + (R70<>"") + (R75<>"") + (R80<>"") = 6, 30, "" ) | W85: =IF( (W55<>"") + (W60<>"") + (W65<>"") + (W70<>"") + (W75<>"") + (W80<>"") = 6, 30, "" ) -> 30 | AB85: =IF( (AB55<>"") + (AB60<>"") + (AB65<>"") + (AB70<>"") + (AB75<>"") + (AB80<>"") = 6, 30, "" )
C87: ='Accepted Drops'!AO69 -> 0 | H87: ='Accepted Drops'!AE69 -> 0 | M87: ='Accepted Drops'!U69 -> 0 | R87: ='Accepted Drops'!K69 -> 20 | W87: ='Accepted Drops'!BI69 -> 1 | AB87: ='Accepted Drops'!AY69 -> 0

Sheet Tile Breakdown
D1: =IFERROR(__xludf.DUMMYFUNCTION("IFERROR(FILTER('Individual Stats'!A:A,'Individual Stats'!Q:Q=""Steel Rings""),{""""})"),"")
C3: Mad Angel | D3: Hueycoatl | E3: Grotesque Guardians | F3: Tormented Demons | G3: Cerberus | H3: Chambers of Xeric
C4: =IFERROR(__xludf.DUMMYFUNCTION("TEXTJOIN(CHAR(10), TRUE, BYROW('Individual Stats'!$A3:$AW20, LAMBDA(r, LET( player, INDEX(r, 1), drops, CHOOSECOLS(r, SEQUENCE(1, 35, 12)), IF(player="""", """", TEXTJOIN(CHAR(10), TRUE, MAP(drops, LAMBDA(drop, IF(drop="""", """", IF(ISNUMBER(SEARCH(C3, "&""""" & drop)), player & "" - "" & TRIM(REGEXREPLACE("""" & drop, ""(?i)^"" & C3 & ""\s*[-–:]*\s*"", """")), """" ) ) )) ) ) ) )) )"),"FearBanana - Hallowfell FearBanana - Hallowfell FearBanana - Hallowfell FearBanana - Hallowfell FearBanana - Hallowfell FearBanana - Hallowfell") -> FearBanana - Hallowfell FearBanana - Hallowfell FearBanana - Hallowfell FearBanana - Hallowfell FearBanana - Hallowfell FearBanana - Hallowfell | D4: =IFERROR(__xludf.DUMMYFUNCTION("TEXTJOIN(CHAR(10), TRUE, BYROW('Individual Stats'!$A3:$AW20, LAMBDA(r, LET( player, INDEX(r, 1), drops, CHOOSECOLS(r, SEQUENCE(1, 35, 12)), IF(player="""", """", TEXTJOIN(CHAR(10), TRUE, MAP(drops, LAMBDA(drop, IF(drop="""", """", IF(ISNUMBER(SEARCH(D3, "&""""" & drop)), player & "" - "" & TRIM(REGEXREPLACE("""" & drop, ""(?i)^"" & D3 & ""\s*[-–:]*\s*"", """")), """" ) ) )) ) ) ) )) )"),"FearBanana - Hueycoatl Hide HareForceOne - Hueycoatl Hide IronDresser - Tome of Earth IronDresser - Hueycoatl Hide JaysunMimosa - Tome of Earth The Beaks - Tome of Earth") -> FearBanana - Hueycoatl Hide HareForceOne - Hueycoatl Hide IronDresser - Tome of Earth IronDresser - Hueycoatl Hide JaysunMimosa - Tome of Earth The Beaks - Tome of Earth | E4: =IFERROR(__xludf.DUMMYFUNCTION("TEXTJOIN(CHAR(10), TRUE, BYROW('Individual Stats'!$A3:$AW20, LAMBDA(r, LET( player, INDEX(r, 1), drops, CHOOSECOLS(r, SEQUENCE(1, 35, 12)), IF(player="""", """", TEXTJOIN(CHAR(10), TRUE, MAP(drops, LAMBDA(drop, IF(drop="""", """", IF(ISNUMBER(SEARCH(E3, "&""""" & drop)), player & "" - "" & TRIM(REGEXREPLACE("""" & drop, ""(?i)^"" & E3 & ""\s*[-–:]*\s*"", """")), """" ) ) )) ) ) ) )) )"),"Foresto - Granite Gloves Foresto - Black Tourmaline Core OdinswrathUN - Granite Ring OdinswrathUN - Granite Maul OdinswrathUN - Granite Maul Suntj - Granite Maul Suntj - Granite Ring") -> Foresto - Granite Gloves Foresto - Black Tourmaline Core OdinswrathUN - Granite Ring OdinswrathUN - Granite Maul OdinswrathUN - Granite Maul Suntj - Granite Maul Suntj - Granite Ring | F4: =IFERROR(__xludf.DUMMYFUNCTION("TEXTJOIN(CHAR(10), TRUE, BYROW('Individual Stats'!$A3:$AW20, LAMBDA(r, LET( player, INDEX(r, 1), drops, CHOOSECOLS(r, SEQUENCE(1, 35, 12)), IF(player="""", """", TEXTJOIN(CHAR(10), TRUE, MAP(drops, LAMBDA(drop, IF(drop="""", """", IF(ISNUMBER(SEARCH(F3, "&""""" & drop)), player & "" - "" & TRIM(REGEXREPLACE("""" & drop, ""(?i)^"" & F3 & ""\s*[-–:]*\s*"", """")), """" ) ) )) ) ) ) )) )"),"JamesMokka - Tormented Synapse Pavlovs dog - Tormented Synapse Swordfish ll - Burning Claw") -> JamesMokka - Tormented Synapse Pavlovs dog - Tormented Synapse Swordfish ll - Burning Claw | G4: =IFERROR(__xludf.DUMMYFUNCTION("TEXTJOIN(CHAR(10), TRUE, BYROW('Individual Stats'!$A3:$AW20, LAMBDA(r, LET( player, INDEX(r, 1), drops, CHOOSECOLS(r, SEQUENCE(1, 35, 12)), IF(player="""", """", TEXTJOIN(CHAR(10), TRUE, MAP(drops, LAMBDA(drop, IF(drop="""", """", IF(ISNUMBER(SEARCH(G3, "&""""" & drop)), player & "" - "" & TRIM(REGEXREPLACE("""" & drop, ""(?i)^"" & G3 & ""\s*[-–:]*\s*"", """")), """" ) ) )) ) ) ) )) )"),"Frangud - Smouldering Stone HareForceOne - Smouldering Stone HareForceOne - Eternal Crystal Lowbob PVM - Eternal Crystal Lowbob PVM - Smouldering Stone sfsd - Eternal Crystal") -> Frangud - Smouldering Stone HareForceOne - Smouldering Stone HareForceOne - Eternal Crystal Lowbob PVM - Eternal Crystal Lowbob PVM - Smouldering Stone sfsd - Eternal Crystal | H4: =IFERROR(__xludf.DUMMYFUNCTION("TEXTJOIN(CHAR(10), TRUE, BYROW('Individual Stats'!$A3:$AW20, LAMBDA(r, LET( player, INDEX(r, 1), drops, CHOOSECOLS(r, SEQUENCE(1, 35, 12)), IF(player="""", """", TEXTJOIN(CHAR(10), TRUE, MAP(drops, LAMBDA(drop, IF(drop="""", """", IF(ISNUMBER(SEARCH(H3, "&""""" & drop)), player & "" - "" & TRIM(REGEXREPLACE("""" & drop, ""(?i)^"" & H3 & ""\s*[-–:]*\s*"", """")), """" ) ) )) ) ) ) )) )"),"Iron bm king - Dexterous Prayer Scroll Iron bm king - Ancestral Piece (any) Iron bm king - Dexterous Prayer Scroll") -> Iron bm king - Dexterous Prayer Scroll Iron bm king - Ancestral Piece (any) Iron bm king - Dexterous Prayer Scroll
C5: Medium Boots | D5: Yama | E5: Tempoross | F5: Theatre of Blood | G5: Mortimer | H5: Demonic Gorillas
C6: =IFERROR(__xludf.DUMMYFUNCTION("TEXTJOIN(CHAR(10), TRUE, BYROW('Individual Stats'!$A3:$AW20, LAMBDA(r, LET( player, INDEX(r, 1), drops, CHOOSECOLS(r, SEQUENCE(1, 35, 12)), IF(player="""", """", TEXTJOIN(CHAR(10), TRUE, MAP(drops, LAMBDA(drop, IF(drop="""", """", IF(ISNUMBER(SEARCH(C5, "&""""" & drop)), player & "" - "" & TRIM(REGEXREPLACE("""" & drop, ""(?i)^"" & C5 & ""\s*[-–:]*\s*"", """")), """" ) ) )) ) ) ) )) )"),"em19em19 - Spiked Manacles Foresto - Ranger Boots Henacy - Holy Sandals UK HMRC - Climbing Boots (g) UK HMRC - Spiked Manacles") -> em19em19 - Spiked Manacles Foresto - Ranger Boots Henacy - Holy Sandals UK HMRC - Climbing Boots (g) UK HMRC - Spiked Manacles | D6: =IFERROR(__xludf.DUMMYFUNCTION("TEXTJOIN(CHAR(10), TRUE, BYROW('Individual Stats'!$A3:$AW20, LAMBDA(r, LET( player, INDEX(r, 1), drops, CHOOSECOLS(r, SEQUENCE(1, 35, 12)), IF(player="""", """", TEXTJOIN(CHAR(10), TRUE, MAP(drops, LAMBDA(drop, IF(drop="""", """", IF(ISNUMBER(SEARCH(D5, "&""""" & drop)), player & "" - "" & TRIM(REGEXREPLACE("""" & drop, ""(?i)^"" & D5 & ""\s*[-–:]*\s*"", """")), """" ) ) )) ) ) ) )) )"),"Papi Aksta - Soulflame Horn") -> Papi Aksta - Soulflame Horn | E6: =IFERROR(__xludf.DUMMYFUNCTION("TEXTJOIN(CHAR(10), TRUE, BYROW('Individual Stats'!$A3:$AW20, LAMBDA(r, LET( player, INDEX(r, 1), drops, CHOOSECOLS(r, SEQUENCE(1, 35, 12)), IF(player="""", """", TEXTJOIN(CHAR(10), TRUE, MAP(drops, LAMBDA(drop, IF(drop="""", """", IF(ISNUMBER(SEARCH(E5, "&""""" & drop)), player & "" - "" & TRIM(REGEXREPLACE("""" & drop, ""(?i)^"" & E5 & ""\s*[-–:]*\s*"", """")), """" ) ) )) ) ) ) )) )"),"ShermyX - Soaked Pages X 25 ShermyX - Tome of Water ShermyX - Soaked Pages X 25 ShermyX - Soaked Pages X 25 ShermyX - Soaked Pages X 25 ShermyX - Soaked Pages X 25 ShermyX - Soaked Pages X 25 ShermyX - Soaked Pages X 25 ShermyX - Soaked Pages X 25") -> ShermyX - Soaked Pages X 25 ShermyX - Tome of Water ShermyX - Soaked Pages X 25 ShermyX - Soaked Pages X 25 ShermyX - Soaked Pages X 25 ShermyX - Soaked Pages X 25 ShermyX - Soaked Pages X 25 ShermyX - Soaked Pages X 25 ShermyX - Soaked Pages X 25 | F6: =IFERROR(__xludf.DUMMYFUNCTION("TEXTJOIN(CHAR(10), TRUE, BYROW('Individual Stats'!$A3:$AW20, LAMBDA(r, LET( player, INDEX(r, 1), drops, CHOOSECOLS(r, SEQUENCE(1, 35, 12)), IF(player="""", """", TEXTJOIN(CHAR(10), TRUE, MAP(drops, LAMBDA(drop, IF(drop="""", """", IF(ISNUMBER(SEARCH(F5, "&""""" & drop)), player & "" - "" & TRIM(REGEXREPLACE("""" & drop, ""(?i)^"" & F5 & ""\s*[-–:]*\s*"", """")), """" ) ) )) ) ) ) )) )"),"") | G6: =IFERROR(__xludf.DUMMYFUNCTION("TEXTJOIN(CHAR(10), TRUE, BYROW('Individual Stats'!$A3:$AW20, LAMBDA(r, LET( player, INDEX(r, 1), drops, CHOOSECOLS(r, SEQUENCE(1, 35, 12)), IF(player="""", """", TEXTJOIN(CHAR(10), TRUE, MAP(drops, LAMBDA(drop, IF(drop="""", """", IF(ISNUMBER(SEARCH(G5, "&""""" & drop)), player & "" - "" & TRIM(REGEXREPLACE("""" & drop, ""(?i)^"" & G5 & ""\s*[-–:]*\s*"", """")), """" ) ) )) ) ) ) )) )"),"Foresto - Belle's Folly Frangud - Dragon Harpoon GIMhimejoshi - Abyssal Whip GIMhimejoshi - Abyssal Head MiaTheDuck3 - Leaf-bladed Sword MiaTheDuck3 - Leaf-bladed Sword MiaTheDuck3 - Leaf-bladed Sword Suntj - Basilisk Head Suntj - Basilisk Jaw") -> Foresto - Belle's Folly Frangud - Dragon Harpoon GIMhimejoshi - Abyssal Whip GIMhimejoshi - Abyssal Head MiaTheDuck3 - Leaf-bladed Sword MiaTheDuck3 - Leaf-bladed Sword MiaTheDuck3 - Leaf-bladed Sword Suntj - Basilisk Head Suntj - Basilisk Jaw | H6: =IFERROR(__xludf.DUMMYFUNCTION("TEXTJOIN(CHAR(10), TRUE, BYROW('Individual Stats'!$A3:$AW20, LAMBDA(r, LET( player, INDEX(r, 1), drops, CHOOSECOLS(r, SEQUENCE(1, 35, 12)), IF(player="""", """", TEXTJOIN(CHAR(10), TRUE, MAP(drops, LAMBDA(drop, IF(drop="""", """", IF(ISNUMBER(SEARCH(H5, "&""""" & drop)), player & "" - "" & TRIM(REGEXREPLACE("""" & drop, ""(?i)^"" & H5 & ""\s*[-–:]*\s*"", """")), """" ) ) )) ) ) ) )) )"),"Foresto - Zenyte Shard IMfinish - Ballista Limbs IMfinish - Ballista Spring IMfinish - Ballista Spring IMfinish - Monkey Tail Swordfish ll - Ballista Limbs Y e l l a a - Monkey Tail") -> Foresto - Zenyte Shard IMfinish - Ballista Limbs IMfinish - Ballista Spring IMfinish - Ballista Spring IMfinish - Monkey Tail Swordfish ll - Ballista Limbs Y e l l a a - Monkey Tail
C7: Godwars Dungeon | D7: Vorkath | E7: Tombs of Amascut | F7: Guardians of the Rift | G7: Phantom Muspah | H7: Royal Titans
C8: =IFERROR(__xludf.DUMMYFUNCTION("TEXTJOIN(CHAR(10), TRUE, BYROW('Individual Stats'!$A3:$AW20, LAMBDA(r, LET( player, INDEX(r, 1), drops, CHOOSECOLS(r, SEQUENCE(1, 35, 12)), IF(player="""", """", TEXTJOIN(CHAR(10), TRUE, MAP(drops, LAMBDA(drop, IF(drop="""", """", IF(ISNUMBER(SEARCH(C7, "&""""" & drop)), player & "" - "" & TRIM(REGEXREPLACE("""" & drop, ""(?i)^"" & C7 & ""\s*[-–:]*\s*"", """")), """" ) ) )) ) ) ) )) )"),"") | D8: =IFERROR(__xludf.DUMMYFUNCTION("TEXTJOIN(CHAR(10), TRUE, BYROW('Individual Stats'!$A3:$AW20, LAMBDA(r, LET( player, INDEX(r, 1), drops, CHOOSECOLS(r, SEQUENCE(1, 35, 12)), IF(player="""", """", TEXTJOIN(CHAR(10), TRUE, MAP(drops, LAMBDA(drop, IF(drop="""", """", IF(ISNUMBER(SEARCH(D7, "&""""" & drop)), player & "" - "" & TRIM(REGEXREPLACE("""" & drop, ""(?i)^"" & D7 & ""\s*[-–:]*\s*"", """")), """" ) ) )) ) ) ) )) )"),"Frangud - Vorkath's Head HareForceOne - Vorkath's Head HareForceOne - Vorkath's Head HareForceOne - Jar of Decay HareForceOne - Vorkath's Head OdinswrathUN - Vorkath's Head Suntj - Vorkath's Head") -> Frangud - Vorkath's Head HareForceOne - Vorkath's Head HareForceOne - Vorkath's Head HareForceOne - Jar of Decay HareForceOne - Vorkath's Head OdinswrathUN - Vorkath's Head Suntj - Vorkath's Head | E8: =IFERROR(__xludf.DUMMYFUNCTION("TEXTJOIN(CHAR(10), TRUE, BYROW('Individual Stats'!$A3:$AW20, LAMBDA(r, LET( player, INDEX(r, 1), drops, CHOOSECOLS(r, SEQUENCE(1, 35, 12)), IF(player="""", """", TEXTJOIN(CHAR(10), TRUE, MAP(drops, LAMBDA(drop, IF(drop="""", """", IF(ISNUMBER(SEARCH(E7, "&""""" & drop)), player & "" - "" & TRIM(REGEXREPLACE("""" & drop, ""(?i)^"" & E7 & ""\s*[-–:]*\s*"", """")), """" ) ) )) ) ) ) )) )"),"JaysunMimosa - Masori Piece (any) Smokey Dro - Lightbearer Smokey Dro - Osmunten's Fang") -> JaysunMimosa - Masori Piece (any) Smokey Dro - Lightbearer Smokey Dro - Osmunten's Fang | F8: =IFERROR(__xludf.DUMMYFUNCTION("TEXTJOIN(CHAR(10), TRUE, BYROW('Individual Stats'!$A3:$AW20, LAMBDA(r, LET( player, INDEX(r, 1), drops, CHOOSECOLS(r, SEQUENCE(1, 35, 12)), IF(player="""", """", TEXTJOIN(CHAR(10), TRUE, MAP(drops, LAMBDA(drop, IF(drop="""", """", IF(ISNUMBER(SEARCH(F7, "&""""" & drop)), player & "" - "" & TRIM(REGEXREPLACE("""" & drop, ""(?i)^"" & F7 & ""\s*[-–:]*\s*"", """")), """" ) ) )) ) ) ) )) )"),"") | G8: =IFERROR(__xludf.DUMMYFUNCTION("TEXTJOIN(CHAR(10), TRUE, BYROW('Individual Stats'!$A3:$AW20, LAMBDA(r, LET( player, INDEX(r, 1), drops, CHOOSECOLS(r, SEQUENCE(1, 35, 12)), IF(player="""", """", TEXTJOIN(CHAR(10), TRUE, MAP(drops, LAMBDA(drop, IF(drop="""", """", IF(ISNUMBER(SEARCH(G7, "&""""" & drop)), player & "" - "" & TRIM(REGEXREPLACE("""" & drop, ""(?i)^"" & G7 & ""\s*[-–:]*\s*"", """")), """" ) ) )) ) ) ) )) )"),"Foresto - Venator Shard Foresto - Venator Shard IronDresser - Venator Shard Suntj - Venator Shard Suntj - Muphin") -> Foresto - Venator Shard Foresto - Venator Shard IronDresser - Venator Shard Suntj - Venator Shard Suntj - Muphin | H8: =IFERROR(__xludf.DUMMYFUNCTION("TEXTJOIN(CHAR(10), TRUE, BYROW('Individual Stats'!$A3:$AW20, LAMBDA(r, LET( player, INDEX(r, 1), drops, CHOOSECOLS(r, SEQUENCE(1, 35, 12)), IF(player="""", """", TEXTJOIN(CHAR(10), TRUE, MAP(drops, LAMBDA(drop, IF(drop="""", """", IF(ISNUMBER(SEARCH(H7, "&""""" & drop)), player & "" - "" & TRIM(REGEXREPLACE("""" & drop, ""(?i)^"" & H7 & ""\s*[-–:]*\s*"", """")), """" ) ) )) ) ) ) )) )"),"FearBanana - Ice Element Staff Crown Frangud - Ice Element Staff Crown Frangud - Bran JaysunMimosa - Mystic Vigour Prayer Scroll Pavlovs dog - Ice Element Staff Crown sfsd - Ice Element Staff Crown The Beaks - Fire Element Staff Crown UK HMRC - Deadeye Pr"&"ayer Scroll UK HMRC - Mystic Vigour Prayer Scroll") -> FearBanana - Ice Element Staff Crown Frangud - Ice Element Staff Crown Frangud - Bran JaysunMimosa - Mystic Vigour Prayer Scroll Pavlovs dog - Ice Element Staff Crown sfsd - Ice Element Staff Crown The Beaks - Fire Element Staff Crown UK HMRC - Deadeye Prayer Scroll UK HMRC - Mystic Vigour Prayer Scroll
C9: Wintertodt | D9: Araxxor | E9: Zulrah | F9: Armoured Zombies | G9: Doom of Mokhaiotl | H9: Abyssal Sire
C10: =IFERROR(__xludf.DUMMYFUNCTION("TEXTJOIN(CHAR(10), TRUE, BYROW('Individual Stats'!$A3:$AW20, LAMBDA(r, LET( player, INDEX(r, 1), drops, CHOOSECOLS(r, SEQUENCE(1, 35, 12)), IF(player="""", """", TEXTJOIN(CHAR(10), TRUE, MAP(drops, LAMBDA(drop, IF(drop="""", """", IF(ISNUMBER(SEARCH(C9, "&""""" & drop)), player & "" - "" & TRIM(REGEXREPLACE("""" & drop, ""(?i)^"" & C9 & ""\s*[-–:]*\s*"", """")), """" ) ) )) ) ) ) )) )"),"ShermyX - Tome of Fire") -> ShermyX - Tome of Fire | D10: =IFERROR(__xludf.DUMMYFUNCTION("TEXTJOIN(CHAR(10), TRUE, BYROW('Individual Stats'!$A3:$AW20, LAMBDA(r, LET( player, INDEX(r, 1), drops, CHOOSECOLS(r, SEQUENCE(1, 35, 12)), IF(player="""", """", TEXTJOIN(CHAR(10), TRUE, MAP(drops, LAMBDA(drop, IF(drop="""", """", IF(ISNUMBER(SEARCH(D9, "&""""" & drop)), player & "" - "" & TRIM(REGEXREPLACE("""" & drop, ""(?i)^"" & D9 & ""\s*[-–:]*\s*"", """")), """" ) ) )) ) ) ) )) )"),"HareForceOne - Araxyte Head IronDresser - Jar of Venom IronDresser - Noxious Piece (any) IronDresser - Noxious Piece (any) IronDresser - Noxious Piece (any) Lowbob PVM - Noxious Piece (any)") -> HareForceOne - Araxyte Head IronDresser - Jar of Venom IronDresser - Noxious Piece (any) IronDresser - Noxious Piece (any) IronDresser - Noxious Piece (any) Lowbob PVM - Noxious Piece (any) | E10: =IFERROR(__xludf.DUMMYFUNCTION("TEXTJOIN(CHAR(10), TRUE, BYROW('Individual Stats'!$A3:$AW20, LAMBDA(r, LET( player, INDEX(r, 1), drops, CHOOSECOLS(r, SEQUENCE(1, 35, 12)), IF(player="""", """", TEXTJOIN(CHAR(10), TRUE, MAP(drops, LAMBDA(drop, IF(drop="""", """", IF(ISNUMBER(SEARCH(E9, "&""""" & drop)), player & "" - "" & TRIM(REGEXREPLACE("""" & drop, ""(?i)^"" & E9 & ""\s*[-–:]*\s*"", """")), """" ) ) )) ) ) ) )) )"),"sfsd - Tanzanite Fang sfsd - Uncut Onyx Swordfish ll - Tanzanite Fang Swordfish ll - Serpentine Visage Swordfish ll - Magic Fang Y e l l a a - Tanzanite Fang") -> sfsd - Tanzanite Fang sfsd - Uncut Onyx Swordfish ll - Tanzanite Fang Swordfish ll - Serpentine Visage Swordfish ll - Magic Fang Y e l l a a - Tanzanite Fang | F10: =IFERROR(__xludf.DUMMYFUNCTION("TEXTJOIN(CHAR(10), TRUE, BYROW('Individual Stats'!$A3:$AW20, LAMBDA(r, LET( player, INDEX(r, 1), drops, CHOOSECOLS(r, SEQUENCE(1, 35, 12)), IF(player="""", """", TEXTJOIN(CHAR(10), TRUE, MAP(drops, LAMBDA(drop, IF(drop="""", """", IF(ISNUMBER(SEARCH(F9, "&""""" & drop)), player & "" - "" & TRIM(REGEXREPLACE("""" & drop, ""(?i)^"" & F9 & ""\s*[-–:]*\s*"", """")), """" ) ) )) ) ) ) )) )"),"Faultiest - Zombie Axe Faultiest - Zombie Helm Faultiest - Zombie Helm Faultiest - Zombie Helm Faultiest - Zombie Helm Faultiest - Zombie Axe Faultiest - Zombie Axe Faultiest - Zombie Axe") -> Faultiest - Zombie Axe Faultiest - Zombie Helm Faultiest - Zombie Helm Faultiest - Zombie Helm Faultiest - Zombie Helm Faultiest - Zombie Axe Faultiest - Zombie Axe Faultiest - Zombie Axe | G10: =IFERROR(__xludf.DUMMYFUNCTION("TEXTJOIN(CHAR(10), TRUE, BYROW('Individual Stats'!$A3:$AW20, LAMBDA(r, LET( player, INDEX(r, 1), drops, CHOOSECOLS(r, SEQUENCE(1, 35, 12)), IF(player="""", """", TEXTJOIN(CHAR(10), TRUE, MAP(drops, LAMBDA(drop, IF(drop="""", """", IF(ISNUMBER(SEARCH(G9, "&""""" & drop)), player & "" - "" & TRIM(REGEXREPLACE("""" & drop, ""(?i)^"" & G9 & ""\s*[-–:]*\s*"", """")), """" ) ) )) ) ) ) )) )"),"Iron bm king - Dom Iron bm king - Dom Papi Aksta - Eye of Ayak") -> Iron bm king - Dom Iron bm king - Dom Papi Aksta - Eye of Ayak | H10: =IFERROR(__xludf.DUMMYFUNCTION("TEXTJOIN(CHAR(10), TRUE, BYROW('Individual Stats'!$A3:$AW20, LAMBDA(r, LET( player, INDEX(r, 1), drops, CHOOSECOLS(r, SEQUENCE(1, 35, 12)), IF(player="""", """", TEXTJOIN(CHAR(10), TRUE, MAP(drops, LAMBDA(drop, IF(drop="""", """", IF(ISNUMBER(SEARCH(H9, "&""""" & drop)), player & "" - "" & TRIM(REGEXREPLACE("""" & drop, ""(?i)^"" & H9 & ""\s*[-–:]*\s*"", """")), """" ) ) )) ) ) ) )) )"),"Frangud - Unsired Frangud - Unsired Lowbob PVM - Unsired Y e l l a a - Unsired Y e l l a a - Unsired") -> Frangud - Unsired Frangud - Unsired Lowbob PVM - Unsired Y e l l a a - Unsired Y e l l a a - Unsired
C11: Alchemical Hydra | D11: Zalcano | E11: Scurrius | F11: Gauntlet | G11: Skilling Tools | H11: Maggot King
C12: =IFERROR(__xludf.DUMMYFUNCTION("TEXTJOIN(CHAR(10), TRUE, BYROW('Individual Stats'!$A3:$AW20, LAMBDA(r, LET( player, INDEX(r, 1), drops, CHOOSECOLS(r, SEQUENCE(1, 35, 12)), IF(player="""", """", TEXTJOIN(CHAR(10), TRUE, MAP(drops, LAMBDA(drop, IF(drop="""", """", IF(ISNUMBER(SEARCH(C11, "&""""" & drop)), player & "" - "" & TRIM(REGEXREPLACE("""" & drop, ""(?i)^"" & C11 & ""\s*[-–:]*\s*"", """")), """" ) ) )) ) ) ) )) )"),"HareForceOne - Hydra's Leather HareForceOne - Hydra's Leather Lowbob PVM - Jar of Chemicals") -> HareForceOne - Hydra's Leather HareForceOne - Hydra's Leather Lowbob PVM - Jar of Chemicals | D12: =IFERROR(__xludf.DUMMYFUNCTION("TEXTJOIN(CHAR(10), TRUE, BYROW('Individual Stats'!$A3:$AW20, LAMBDA(r, LET( player, INDEX(r, 1), drops, CHOOSECOLS(r, SEQUENCE(1, 35, 12)), IF(player="""", """", TEXTJOIN(CHAR(10), TRUE, MAP(drops, LAMBDA(drop, IF(drop="""", """", IF(ISNUMBER(SEARCH(D11, "&""""" & drop)), player & "" - "" & TRIM(REGEXREPLACE("""" & drop, ""(?i)^"" & D11 & ""\s*[-–:]*\s*"", """")), """" ) ) )) ) ) ) )) )"),"JaysunMimosa - Crystal Tool Seed") -> JaysunMimosa - Crystal Tool Seed | E12: =IFERROR(__xludf.DUMMYFUNCTION("TEXTJOIN(CHAR(10), TRUE, BYROW('Individual Stats'!$A3:$AW20, LAMBDA(r, LET( player, INDEX(r, 1), drops, CHOOSECOLS(r, SEQUENCE(1, 35, 12)), IF(player="""", """", TEXTJOIN(CHAR(10), TRUE, MAP(drops, LAMBDA(drop, IF(drop="""", """", IF(ISNUMBER(SEARCH(E11, "&""""" & drop)), player & "" - "" & TRIM(REGEXREPLACE("""" & drop, ""(?i)^"" & E11 & ""\s*[-–:]*\s*"", """")), """" ) ) )) ) ) ) )) )"),"Foresto - Scurrius' Spine Gas Stone86 - Scurrius' Spine Gas Stone86 - Scurrius' Spine JamesMokka - Scurrius' Spine MiaTheDuck3 - Scurrius' Spine Pavlovs dog - Scurrius' Spine Pavlovs dog - Scurrius' Spine Pavlovs dog - Scurrius' Spine Suntj - Scurrius' Sp"&"ine Suntj - Scurrius' Spine") -> Foresto - Scurrius' Spine Gas Stone86 - Scurrius' Spine Gas Stone86 - Scurrius' Spine JamesMokka - Scurrius' Spine MiaTheDuck3 - Scurrius' Spine Pavlovs dog - Scurrius' Spine Pavlovs dog - Scurrius' Spine Pavlovs dog - Scurrius' Spine Suntj - Scurrius' Spine Suntj - Scurrius' Spine | F12: =IFERROR(__xludf.DUMMYFUNCTION("TEXTJOIN(CHAR(10), TRUE, BYROW('Individual Stats'!$A3:$AW20, LAMBDA(r, LET( player, INDEX(r, 1), drops, CHOOSECOLS(r, SEQUENCE(1, 35, 12)), IF(player="""", """", TEXTJOIN(CHAR(10), TRUE, MAP(drops, LAMBDA(drop, IF(drop="""", """", IF(ISNUMBER(SEARCH(F11, "&""""" & drop)), player & "" - "" & TRIM(REGEXREPLACE("""" & drop, ""(?i)^"" & F11 & ""\s*[-–:]*\s*"", """")), """" ) ) )) ) ) ) )) )"),"Frangud - Crystal Armour Seed IronDresser - Crystal Weapon Seed IronDresser - Crystal Weapon Seed Pavlovs dog - Crystal Weapon Seed Pavlovs dog - Enhanced Crystal Weapon Seed Suntj - Crystal Weapon Seed") -> Frangud - Crystal Armour Seed IronDresser - Crystal Weapon Seed IronDresser - Crystal Weapon Seed Pavlovs dog - Crystal Weapon Seed Pavlovs dog - Enhanced Crystal Weapon Seed Suntj - Crystal Weapon Seed | G12: =IFERROR(__xludf.DUMMYFUNCTION("TEXTJOIN(CHAR(10), TRUE, BYROW('Individual Stats'!$A3:$AW20, LAMBDA(r, LET( player, INDEX(r, 1), drops, CHOOSECOLS(r, SEQUENCE(1, 35, 12)), IF(player="""", """", TEXTJOIN(CHAR(10), TRUE, MAP(drops, LAMBDA(drop, IF(drop="""", """", IF(ISNUMBER(SEARCH(G11, "&""""" & drop)), player & "" - "" & TRIM(REGEXREPLACE("""" & drop, ""(?i)^"" & G11 & ""\s*[-–:]*\s*"", """")), """" ) ) )) ) ) ) )) )"),"FearBanana - Jeweller's Chisel IMfinish - Fletching Knife IMfinish - Jeweller's Chisel UK HMRC - Jeweller's Chisel") -> FearBanana - Jeweller's Chisel IMfinish - Fletching Knife IMfinish - Jeweller's Chisel UK HMRC - Jeweller's Chisel | H12: =IFERROR(__xludf.DUMMYFUNCTION("TEXTJOIN(CHAR(10), TRUE, BYROW('Individual Stats'!$A3:$AW20, LAMBDA(r, LET( player, INDEX(r, 1), drops, CHOOSECOLS(r, SEQUENCE(1, 35, 12)), IF(player="""", """", TEXTJOIN(CHAR(10), TRUE, MAP(drops, LAMBDA(drop, IF(drop="""", """", IF(ISNUMBER(SEARCH(H11, "&""""" & drop)), player & "" - "" & TRIM(REGEXREPLACE("""" & drop, ""(?i)^"" & H11 & ""\s*[-–:]*\s*"", """")), """" ) ) )) ) ) ) )) )"),"Arcane0214 - Elder Venator Fang") -> Arcane0214 - Elder Venator Fang
C13: Thieving | D13: Barrows | E13: DT2 Bosses | F13: Wilderness Trio | G13: Dagannoth Kings | H13: Moons of Peril
C14: =IFERROR(__xludf.DUMMYFUNCTION("TEXTJOIN(CHAR(10), TRUE, BYROW('Individual Stats'!$A3:$AW20, LAMBDA(r, LET( player, INDEX(r, 1), drops, CHOOSECOLS(r, SEQUENCE(1, 35, 12)), IF(player="""", """", TEXTJOIN(CHAR(10), TRUE, MAP(drops, LAMBDA(drop, IF(drop="""", """", IF(ISNUMBER(SEARCH(C13, "&""""" & drop)), player & "" - "" & TRIM(REGEXREPLACE("""" & drop, ""(?i)^"" & C13 & ""\s*[-–:]*\s*"", """")), """" ) ) )) ) ) ) )) )"),"em19em19 - Enhanced Crystal Teleport Seed Papi Aksta - Blood Shard Papi Aksta - Enhanced Crystal Teleport Seed") -> em19em19 - Enhanced Crystal Teleport Seed Papi Aksta - Blood Shard Papi Aksta - Enhanced Crystal Teleport Seed | D14: =IFERROR(__xludf.DUMMYFUNCTION("TEXTJOIN(CHAR(10), TRUE, BYROW('Individual Stats'!$A3:$AW20, LAMBDA(r, LET( player, INDEX(r, 1), drops, CHOOSECOLS(r, SEQUENCE(1, 35, 12)), IF(player="""", """", TEXTJOIN(CHAR(10), TRUE, MAP(drops, LAMBDA(drop, IF(drop="""", """", IF(ISNUMBER(SEARCH(D13, "&""""" & drop)), player & "" - "" & TRIM(REGEXREPLACE("""" & drop, ""(?i)^"" & D13 & ""\s*[-–:]*\s*"", """")), """" ) ) )) ) ) ) )) )"),"Foresto - Verac's Piece (any) Pavlovs dog - Ahrim's Piece (any) Pavlovs dog - Dharok's Piece (any) Pavlovs dog - Verac's Piece (any) Pavlovs dog - Dharok's Piece (any) Pavlovs dog - Torag's Piece (any) Pavlovs dog - Karil's Piece (any) Pavlovs dog - Karil"&"'s Piece (any) Pavlovs dog - Verac's Piece (any) Pavlovs dog - Torag's Piece (any) UK HMRC - Dharok's Piece (any) UK HMRC - Karil's Piece (any)") -> Foresto - Verac's Piece (any) Pavlovs dog - Ahrim's Piece (any) Pavlovs dog - Dharok's Piece (any) Pavlovs dog - Verac's Piece (any) Pavlovs dog - Dharok's Piece (any) Pavlovs dog - Torag's Piece (any) Pavlovs dog - Karil's Piece (any) Pavlovs dog - Karil's Piece (any) Pavlovs dog - Verac's Piece (any) Pavlovs dog - Torag's Piece (any) UK HMRC - Dharok's Piece (any) UK HMRC - Karil's Piece (any) | E14: =IFERROR(__xludf.DUMMYFUNCTION("TEXTJOIN(CHAR(10), TRUE, BYROW('Individual Stats'!$A3:$AW20, LAMBDA(r, LET( player, INDEX(r, 1), drops, CHOOSECOLS(r, SEQUENCE(1, 35, 12)), IF(player="""", """", TEXTJOIN(CHAR(10), TRUE, MAP(drops, LAMBDA(drop, IF(drop="""", """", IF(ISNUMBER(SEARCH(E13, "&""""" & drop)), player & "" - "" & TRIM(REGEXREPLACE("""" & drop, ""(?i)^"" & E13 & ""\s*[-–:]*\s*"", """")), """" ) ) )) ) ) ) )) )"),"Bear clogs - Blood Quartz Bear clogs - Virtus Piece (any) Bear clogs - Ultor Vestige (+ 2x gold ring) IronDresser - Blood Quartz JaysunMimosa - Chromium Ingot Pavlovs dog - Virtus Piece (any)") -> Bear clogs - Blood Quartz Bear clogs - Virtus Piece (any) Bear clogs - Ultor Vestige (+ 2x gold ring) IronDresser - Blood Quartz JaysunMimosa - Chromium Ingot Pavlovs dog - Virtus Piece (any) | F14: =IFERROR(__xludf.DUMMYFUNCTION("TEXTJOIN(CHAR(10), TRUE, BYROW('Individual Stats'!$A3:$AW20, LAMBDA(r, LET( player, INDEX(r, 1), drops, CHOOSECOLS(r, SEQUENCE(1, 35, 12)), IF(player="""", """", TEXTJOIN(CHAR(10), TRUE, MAP(drops, LAMBDA(drop, IF(drop="""", """", IF(ISNUMBER(SEARCH(F13, "&""""" & drop)), player & "" - "" & TRIM(REGEXREPLACE("""" & drop, ""(?i)^"" & F13 & ""\s*[-–:]*\s*"", """")), """" ) ) )) ) ) ) )) )"),"Bear clogs - Ring (any) Bear clogs - Dragon 2h Sword Bear clogs - Pet IMfinish - Pet IMfinish - Fangs of Venenatis IMfinish - Dragon 2h Sword IMfinish - Dragon Pickaxe IMfinish - Dragon Pickaxe MiaTheDuck3 - Dragon Pickaxe") -> Bear clogs - Ring (any) Bear clogs - Dragon 2h Sword Bear clogs - Pet IMfinish - Pet IMfinish - Fangs of Venenatis IMfinish - Dragon 2h Sword IMfinish - Dragon Pickaxe IMfinish - Dragon Pickaxe MiaTheDuck3 - Dragon Pickaxe | G14: =IFERROR(__xludf.DUMMYFUNCTION("TEXTJOIN(CHAR(10), TRUE, BYROW('Individual Stats'!$A3:$AW20, LAMBDA(r, LET( player, INDEX(r, 1), drops, CHOOSECOLS(r, SEQUENCE(1, 35, 12)), IF(player="""", """", TEXTJOIN(CHAR(10), TRUE, MAP(drops, LAMBDA(drop, IF(drop="""", """", IF(ISNUMBER(SEARCH(G13, "&""""" & drop)), player & "" - "" & TRIM(REGEXREPLACE("""" & drop, ""(?i)^"" & G13 & ""\s*[-–:]*\s*"", """")), """" ) ) )) ) ) ) )) )"),"Rs Kill King - Seercull Rs Kill King - Rings (other) Suntj - Rings (other) Suntj - Seercull Suntj - Rings (other) Suntj - Rings (other) Suntj - Dragon axe Suntj - Berserker Ring Y e l l a a - Rings (other) Y e l l a a - Dragon axe") -> Rs Kill King - Seercull Rs Kill King - Rings (other) Suntj - Rings (other) Suntj - Seercull Suntj - Rings (other) Suntj - Rings (other) Suntj - Dragon axe Suntj - Berserker Ring Y e l l a a - Rings (other) Y e l l a a - Dragon axe | H14: =IFERROR(__xludf.DUMMYFUNCTION("TEXTJOIN(CHAR(10), TRUE, BYROW('Individual Stats'!$A3:$AW20, LAMBDA(r, LET( player, INDEX(r, 1), drops, CHOOSECOLS(r, SEQUENCE(1, 35, 12)), IF(player="""", """", TEXTJOIN(CHAR(10), TRUE, MAP(drops, LAMBDA(drop, IF(drop="""", """", IF(ISNUMBER(SEARCH(H13, "&""""" & drop)), player & "" - "" & TRIM(REGEXREPLACE("""" & drop, ""(?i)^"" & H13 & ""\s*[-–:]*\s*"", """")), """" ) ) )) ) ) ) )) )"),"FearBanana - Blue Moon Piece (any) FearBanana - Eclipse Moon Piece (any) Gas Stone86 - Blue Moon Piece (any) MiaTheDuck3 - Blue Moon Piece (any) Smokey Dro - Eclipse Moon Piece (any) UK HMRC - Blue Moon Piece (any) vainqueurs - Blood Moon Piece (any) vain"&"queurs - Blood Moon Piece (any)") -> FearBanana - Blue Moon Piece (any) FearBanana - Eclipse Moon Piece (any) Gas Stone86 - Blue Moon Piece (any) MiaTheDuck3 - Blue Moon Piece (any) Smokey Dro - Eclipse Moon Piece (any) UK HMRC - Blue Moon Piece (any) vainqueurs - Blood Moon Piece (any) vainqueurs - Blood Moon Piece (any)
C17: Nex | D17: Nightmare | E17: Megarares | F17: Jar/Pet | G17: Colosseum | H17: Corporeal Beast
C18: =IFERROR(__xludf.DUMMYFUNCTION("TEXTJOIN(CHAR(10), TRUE, BYROW('Individual Stats'!$A3:$AW20, LAMBDA(r, LET( player, INDEX(r, 1), drops, CHOOSECOLS(r, SEQUENCE(1, 35, 12)), IF(player="""", """", TEXTJOIN(CHAR(10), TRUE, MAP(drops, LAMBDA(drop, IF(drop="""", """", IF(ISNUMBER(SEARCH(C17, "&""""" & drop)), player & "" - "" & TRIM(REGEXREPLACE("""" & drop, ""(?i)^"" & C17 & ""\s*[-–:]*\s*"", """")), """" ) ) )) ) ) ) )) )"),"") | D18: =IFERROR(__xludf.DUMMYFUNCTION("TEXTJOIN(CHAR(10), TRUE, BYROW('Individual Stats'!$A3:$AW20, LAMBDA(r, LET( player, INDEX(r, 1), drops, CHOOSECOLS(r, SEQUENCE(1, 35, 12)), IF(player="""", """", TEXTJOIN(CHAR(10), TRUE, MAP(drops, LAMBDA(drop, IF(drop="""", """", IF(ISNUMBER(SEARCH(D17, "&""""" & drop)), player & "" - "" & TRIM(REGEXREPLACE("""" & drop, ""(?i)^"" & D17 & ""\s*[-–:]*\s*"", """")), """" ) ) )) ) ) ) )) )"),"") | E18: =IFERROR(__xludf.DUMMYFUNCTION("TEXTJOIN(CHAR(10), TRUE, BYROW('Individual Stats'!$A3:$AW20, LAMBDA(r, LET( player, INDEX(r, 1), drops, CHOOSECOLS(r, SEQUENCE(1, 35, 12)), IF(player="""", """", TEXTJOIN(CHAR(10), TRUE, MAP(drops, LAMBDA(drop, IF(drop="""", """", IF(ISNUMBER(SEARCH(E17, "&""""" & drop)), player & "" - "" & TRIM(REGEXREPLACE("""" & drop, ""(?i)^"" & E17 & ""\s*[-–:]*\s*"", """")), """" ) ) )) ) ) ) )) )"),"") | F18: =IFERROR(__xludf.DUMMYFUNCTION("TEXTJOIN(CHAR(10), TRUE, BYROW('Individual Stats'!$A3:$AW20, LAMBDA(r, LET( player, INDEX(r, 1), drops, CHOOSECOLS(r, SEQUENCE(1, 35, 12)), IF(player="""", """", TEXTJOIN(CHAR(10), TRUE, MAP(drops, LAMBDA(drop, IF(drop="""", """", IF(ISNUMBER(SEARCH(F17, "&""""" & drop)), player & "" - "" & TRIM(REGEXREPLACE("""" & drop, ""(?i)^"" & F17 & ""\s*[-–:]*\s*"", """")), """" ) ) )) ) ) ) )) )"),"Bear clogs - Pet Frangud - Jar HareForceOne - Jar IMfinish - Pet Iron bm king - Pet IronDresser - Jar Lowbob PVM - Jar Suntj - Pet Y e l l a a - Pet") -> Bear clogs - Pet Frangud - Jar HareForceOne - Jar IMfinish - Pet Iron bm king - Pet IronDresser - Jar Lowbob PVM - Jar Suntj - Pet Y e l l a a - Pet | G18: =IFERROR(__xludf.DUMMYFUNCTION("TEXTJOIN(CHAR(10), TRUE, BYROW('Individual Stats'!$A3:$AW20, LAMBDA(r, LET( player, INDEX(r, 1), drops, CHOOSECOLS(r, SEQUENCE(1, 35, 12)), IF(player="""", """", TEXTJOIN(CHAR(10), TRUE, MAP(drops, LAMBDA(drop, IF(drop="""", """", IF(ISNUMBER(SEARCH(G17, "&""""" & drop)), player & "" - "" & TRIM(REGEXREPLACE("""" & drop, ""(?i)^"" & G17 & ""\s*[-–:]*\s*"", """")), """" ) ) )) ) ) ) )) )"),"Rs Kill King - Fortis Colosseum - Sunfire fanatic chausses Rs Kill King - Fortis Colosseum - Echo crystal(s) (1-3)") -> Rs Kill King - Fortis Colosseum - Sunfire fanatic chausses Rs Kill King - Fortis Colosseum - Echo crystal(s) (1-3) | H18: =IFERROR(__xludf.DUMMYFUNCTION("TEXTJOIN(CHAR(10), TRUE, BYROW('Individual Stats'!$A3:$AW20, LAMBDA(r, LET( player, INDEX(r, 1), drops, CHOOSECOLS(r, SEQUENCE(1, 35, 12)), IF(player="""", """", TEXTJOIN(CHAR(10), TRUE, MAP(drops, LAMBDA(drop, IF(drop="""", """", IF(ISNUMBER(SEARCH(H17, "&""""" & drop)), player & "" - "" & TRIM(REGEXREPLACE("""" & drop, ""(?i)^"" & H17 & ""\s*[-–:]*\s*"", """")), """" ) ) )) ) ) ) )) )"),"")

Sheet Individual Stats
B1: P R E - V E R I F I C A T I O N | O1: S U B M I S S I O N S
A2: Members | B2: WT | C2: Tempo | D2: Clues | E2: GOTR | F2: Yama | G2: Blood Shard | H2: Teleport Seed | I2: Chisel | J2: Hammer | K2: Knife | L2: Points | M2: Tiles | N2: Total GP | O2: 1 | P2: 2 | Q2: 3 | R2: 4 | S2: 5 | T2: 6 | U2: 7 | V2: 8 | W2: 9 | X2: 10 | Y2: 11 | Z2: 12 | AA2: 13 | AB2: 14 | AC2: 15 | AD2: 16 | AE2: 17 | AF2: 18 | AG2: 19 | AH2: 20 | AI2: 21 | AJ2: 22 | AK2: 23 | AL2: 24 | AM2: 25 | AN2: 26 | AO2: 27 | AP2: 28 | AQ2: 29 | AR2: 30 | AS2: 31 | AT2: 32 | AU2: 33 | AV2: 34 | AW2: 35
A3: Arcane0214 | L3: {=SUM(IF( 'Individual Stats'!O3:AW3="", 0, IFERROR( VLOOKUP( 'Individual Stats'!O3:AW3, 'Accepted Drops'!$B$84:$R$328, 17, FALSE ), 0 ) ))} -> 10 | M3: =COUNTA(O3:AM3) -> 1 | N3: {=SUM(IFERROR(VLOOKUP('Tradeable Drops'!B3:AF3, {'Accepted Drops'!$AG$83:$AG$330,'Accepted Drops'!$AC$83:$AC$330}, 2, 0),0))} -> 123112552 | O3: Maggot King - Elder Venator Fang
A4: Bear clogs | L4: {=SUM(IF( 'Individual Stats'!O4:AW4="", 0, IFERROR( VLOOKUP( 'Individual Stats'!O4:AW4, 'Accepted Drops'!$B$84:$R$328, 17, FALSE ), 0 ) ))} -> 27.222222 | M4: =COUNTA(O4:AM4) -> 9 | N4: {=SUM(IFERROR(VLOOKUP('Tradeable Drops'!B4:AF4, {'Accepted Drops'!$AG$83:$AG$330,'Accepted Drops'!$AC$83:$AC$330}, 2, 0),0))} -> 119318274 | O4: DT2 Bosses - Blood Quartz | P4: DT2 Bosses - Virtus Piece (any) | Q4: DT2 Bosses - Ultor Vestige (+ 2x gold ring) | R4: Wilderness Trio - Ring (any) | S4: Wilderness Trio - Dragon 2h Sword | T4: Wilderness Trio - Pet | U4: Jar/Pet - Pet | V4: God Wars Dungeon - Godsword Shard (any) | W4: God Wars Dungeon - Godsword Shard (any)
A5: em19em19 | B5: ✅ | C5: ✅ | D5: ✅ | E5: ✅ | I5: ✅ | L5: {=SUM(IF( 'Individual Stats'!O5:AW5="", 0, IFERROR( VLOOKUP( 'Individual Stats'!O5:AW5, 'Accepted Drops'!$B$84:$R$328, 17, FALSE ), 0 ) ))} -> 6.3333333 | M5: =COUNTA(O5:AM5) -> 3 | N5: {=SUM(IFERROR(VLOOKUP('Tradeable Drops'!B5:AF5, {'Accepted Drops'!$AG$83:$AG$330,'Accepted Drops'!$AC$83:$AC$330}, 2, 0),0))} -> 3575510 | O5: Medium Boots - Spiked Manacles | P5: Thieving - Enhanced Crystal Teleport Seed | Q5: GOTR - Abyssal Dye (any)
A6: Excadriill | D6: ✅ | L6: {=SUM(IF( 'Individual Stats'!O6:AW6="", 0, IFERROR( VLOOKUP( 'Individual Stats'!O6:AW6, 'Accepted Drops'!$B$84:$R$328, 17, FALSE ), 0 ) ))} -> 0 | M6: =COUNTA(O6:AM6) -> 0 | N6: {=SUM(IFERROR(VLOOKUP('Tradeable Drops'!B6:AF6, {'Accepted Drops'!$AG$83:$AG$330,'Accepted Drops'!$AC$83:$AC$330}, 2, 0),0))} -> 0
A7: Faultiest | E7: ✅ | L7: {=SUM(IF( 'Individual Stats'!O7:AW7="", 0, IFERROR( VLOOKUP( 'Individual Stats'!O7:AW7, 'Accepted Drops'!$B$84:$R$328, 17, FALSE ), 0 ) ))} -> 5.5 | M7: =COUNTA(O7:AM7) -> 9 | N7: {=SUM(IFERROR(VLOOKUP('Tradeable Drops'!B7:AF7, {'Accepted Drops'!$AG$83:$AG$330,'Accepted Drops'!$AC$83:$AC$330}, 2, 0),0))} -> 7519184 | O7: GOTR - Elemental Talisman | P7: Armoured Zombies - Zombie Axe | Q7: Armoured Zombies - Zombie Helm | R7: Armoured Zombies - Zombie Helm | S7: Armoured Zombies - Zombie Helm | T7: Armoured Zombies - Zombie Helm | U7: Armoured Zombies - Zombie Axe | V7: Armoured Zombies - Zombie Axe | W7: Armoured Zombies - Zombie Axe
A8: FearBanana | B8: ✅ | C8: ✅ | D8: ✅ | E8: ✅ | I8: ✅ | J8: ✅ | K8: ✅ | L8: {=SUM(IF( 'Individual Stats'!O8:AW8="", 0, IFERROR( VLOOKUP( 'Individual Stats'!O8:AW8, 'Accepted Drops'!$B$84:$R$328, 17, FALSE ), 0 ) ))} -> 9.875 | M8: =COUNTA(O8:AM8) -> 12 | N8: {=SUM(IFERROR(VLOOKUP('Tradeable Drops'!B8:AF8, {'Accepted Drops'!$AG$83:$AG$330,'Accepted Drops'!$AC$83:$AC$330}, 2, 0),0))} -> 13798992 | O8: Moons of Peril - Blue Moon Piece (any) | P8: Moons of Peril - Eclipse Moon Piece (any) | Q8: Skilling Tools - Jeweller's Chisel | R8: GOTR - Catalytic Talisman | S8: Mad Angel - Hallowfell | T8: Mad Angel - Hallowfell | U8: Mad Angel - Hallowfell | V8: Mad Angel - Hallowfell | W8: Mad Angel - Hallowfell | X8: Mad Angel - Hallowfell | Y8: Hueycoatl - Hueycoatl Hide | Z8: Royal Titans - Ice Element Staff Crown
A9: Foresto | D9: ✅ | L9: {=SUM(IF( 'Individual Stats'!O9:AW9="", 0, IFERROR( VLOOKUP( 'Individual Stats'!O9:AW9, 'Accepted Drops'!$B$84:$R$328, 17, FALSE ), 0 ) ))} -> 13.333333 | M9: =COUNTA(O9:AM9) -> 9 | N9: {=SUM(IFERROR(VLOOKUP('Tradeable Drops'!B9:AF9, {'Accepted Drops'!$AG$83:$AG$330,'Accepted Drops'!$AC$83:$AC$330}, 2, 0),0))} -> 78465370 | O9: Barrows - Verac's Piece (any) | P9: Grotesque Guardians - Granite Gloves | Q9: Grotesque Guardians - Black Tourmaline Core | R9: Mortimer - Belle's Folly | S9: Scurrius - Scurrius' Spine | T9: Medium Boots - Ranger Boots | U9: Demonic Gorillas - Zenyte Shard | V9: Phantom Muspah - Venator Shard | W9: Phantom Muspah - Venator Shard
A10: Frangud | D10: ✅ | F10: ✅ | J10: ✅ | L10: {=SUM(IF( 'Individual Stats'!O10:AW10="", 0, IFERROR( VLOOKUP( 'Individual Stats'!O10:AW10, 'Accepted Drops'!$B$84:$R$328, 17, FALSE ), 0 ) ))} -> 15.75 | M10: =COUNTA(O10:AM10) -> 9 | N10: {=SUM(IFERROR(VLOOKUP('Tradeable Drops'!B10:AF10, {'Accepted Drops'!$AG$83:$AG$330,'Accepted Drops'!$AC$83:$AC$330}, 2, 0),0))} -> 15718678 | O10: Gauntlet - Crystal Armour Seed | P10: Royal Titans - Ice Element Staff Crown | Q10: Royal Titans - Bran | R10: Mortimer - Dragon Harpoon | S10: Vorkath - Vorkath's Head | T10: Abyssal Sire - Unsired | U10: Abyssal Sire - Unsired | V10: Jar/Pet - Jar | W10: Cerberus - Smouldering Stone
A11: Gas Stone86 | L11: {=SUM(IF( 'Individual Stats'!O11:AW11="", 0, IFERROR( VLOOKUP( 'Individual Stats'!O11:AW11, 'Accepted Drops'!$B$84:$R$328, 17, FALSE ), 0 ) ))} -> 1.625 | M11: =COUNTA(O11:AM11) -> 3 | N11: {=SUM(IFERROR(VLOOKUP('Tradeable Drops'!B11:AF11, {'Accepted Drops'!$AG$83:$AG$330,'Accepted Drops'!$AC$83:$AC$330}, 2, 0),0))} -> 331008 | O11: Moons of Peril - Blue Moon Piece (any) | P11: Scurrius - Scurrius' Spine | Q11: Scurrius - Scurrius' Spine
A12: GIMhimejoshi | B12: ✅ | C12: ✅ | D12: ✅ | E12: ✅ | J12: ✅ | L12: {=SUM(IF( 'Individual Stats'!O12:AW12="", 0, IFERROR( VLOOKUP( 'Individual Stats'!O12:AW12, 'Accepted Drops'!$B$84:$R$328, 17, FALSE ), 0 ) ))} -> 2 | M12: =COUNTA(O12:AM12) -> 2 | N12: {=SUM(IFERROR(VLOOKUP('Tradeable Drops'!B12:AF12, {'Accepted Drops'!$AG$83:$AG$330,'Accepted Drops'!$AC$83:$AC$330}, 2, 0),0))} -> 801099 | O12: Mortimer - Abyssal Whip | P12: Mortimer - Abyssal Head
A13: HareForceOne | B13: ✅ | C13: ✅ | D13: ✅ | E13: ✅ | F13: ✅ | I13: ✅ | J13: ✅ | K13: ✅ | L13: {=SUM(IF( 'Individual Stats'!O13:AW13="", 0, IFERROR( VLOOKUP( 'Individual Stats'!O13:AW13, 'Accepted Drops'!$B$84:$R$328, 17, FALSE ), 0 ) ))} -> 31.791667 | M13: =COUNTA(O13:AM13) -> 11 | N13: {=SUM(IFERROR(VLOOKUP('Tradeable Drops'!B13:AF13, {'Accepted Drops'!$AG$83:$AG$330,'Accepted Drops'!$AC$83:$AC$330}, 2, 0),0))} -> 27501950 | O13: Hueycoatl - Hueycoatl Hide | P13: Araxxor - Araxyte Head | Q13: Vorkath - Vorkath's Head | R13: Vorkath - Vorkath's Head | S13: Vorkath - Jar of Decay | T13: Jar/Pet - Jar | U13: Vorkath - Vorkath's Head | V13: Alchemical Hydra - Hydra's Leather | W13: Alchemical Hydra - Hydra's Leather | X13: Cerberus - Smouldering Stone | Y13: Cerberus - Eternal Crystal
A14: Henacy | D14: ✅ | E14: ✅ | L14: {=SUM(IF( 'Individual Stats'!O14:AW14="", 0, IFERROR( VLOOKUP( 'Individual Stats'!O14:AW14, 'Accepted Drops'!$B$84:$R$328, 17, FALSE ), 0 ) ))} -> 2.5 | M14: =COUNTA(O14:AM14) -> 2 | N14: {=SUM(IFERROR(VLOOKUP('Tradeable Drops'!B14:AF14, {'Accepted Drops'!$AG$83:$AG$330,'Accepted Drops'!$AC$83:$AC$330}, 2, 0),0))} -> 896607 | O14: Medium Boots - Holy Sandals | P14: GOTR - Catalytic Talisman
A15: IMfinish | D15: ✅ | I15: ✅ | K15: ✅ | L15: {=SUM(IF( 'Individual Stats'!O15:AW15="", 0, IFERROR( VLOOKUP( 'Individual Stats'!O15:AW15, 'Accepted Drops'!$B$84:$R$328, 17, FALSE ), 0 ) ))} -> 19.5 | M15: =COUNTA(O15:AM15) -> 12 | N15: {=SUM(IFERROR(VLOOKUP('Tradeable Drops'!B15:AF15, {'Accepted Drops'!$AG$83:$AG$330,'Accepted Drops'!$AC$83:$AC$330}, 2, 0),0))} -> 1954843 | O15: Skilling Tools - Fletching Knife | P15: Demonic Gorillas - Ballista Limbs | Q15: Demonic Gorillas - Ballista Spring | R15: Skilling Tools - Jeweller's Chisel | S15: Demonic Gorillas - Ballista Spring | T15: Demonic Gorillas - Monkey Tail | U15: Wilderness Trio - Pet | V15: Jar/Pet - Pet | W15: Wilderness Trio - Fangs of Venenatis | X15: Wilderness Trio - Dragon 2h Sword | Y15: Wilderness Trio - Dragon Pickaxe | Z15: Wilderness Trio - Dragon Pickaxe
A16: Iron bm king | L16: {=SUM(IF( 'Individual Stats'!O16:AW16="", 0, IFERROR( VLOOKUP( 'Individual Stats'!O16:AW16, 'Accepted Drops'!$B$84:$R$328, 17, FALSE ), 0 ) ))} -> 35.333333 | M16: =COUNTA(O16:AM16) -> 6 | N16: {=SUM(IFERROR(VLOOKUP('Tradeable Drops'!B16:AF16, {'Accepted Drops'!$AG$83:$AG$330,'Accepted Drops'!$AC$83:$AC$330}, 2, 0),0))} -> 110546106 | O16: Doom of Mokhaiotl - Dom | P16: Jar/Pet - Pet | Q16: Chambers of Xeric - Dexterous Prayer Scroll | R16: Doom of Mokhaiotl - Dom | S16: Chambers of Xeric - Ancestral Piece (any) | T16: Chambers of Xeric - Dexterous Prayer Scroll
A17: IronDresser | D17: ✅ | L17: {=SUM(IF( 'Individual Stats'!O17:AW17="", 0, IFERROR( VLOOKUP( 'Individual Stats'!O17:AW17, 'Accepted Drops'!$B$84:$R$328, 17, FALSE ), 0 ) ))} -> 28.097222 | M17: =COUNTA(O17:AM17) -> 12 | N17: {=SUM(IFERROR(VLOOKUP('Tradeable Drops'!B17:AF17, {'Accepted Drops'!$AG$83:$AG$330,'Accepted Drops'!$AC$83:$AC$330}, 2, 0),0))} -> 55511421 | O17: Gauntlet - Crystal Weapon Seed | P17: Gauntlet - Crystal Weapon Seed | Q17: Araxxor - Jar of Venom | R17: Araxxor - Noxious Piece (any) | S17: Jar/Pet - Jar | T17: Hueycoatl - Tome of Earth | U17: Hueycoatl - Hueycoatl Hide | V17: DT2 Bosses - Blood Quartz | W17: Araxxor - Noxious Piece (any) | X17: Araxxor - Noxious Piece (any) | Y17: Phantom Muspah - Venator Shard | Z17: God Wars Dungeon - Saradomin Sword
A18: JamesMokka | B18: ✅ | C18: ✅ | D18: ✅ | E18: ✅ | I18: ✅ | L18: {=SUM(IF( 'Individual Stats'!O18:AW18="", 0, IFERROR( VLOOKUP( 'Individual Stats'!O18:AW18, 'Accepted Drops'!$B$84:$R$328, 17, FALSE ), 0 ) ))} -> 3.8333333 | M18: =COUNTA(O18:AM18) -> 2 | N18: {=SUM(IFERROR(VLOOKUP('Tradeable Drops'!B18:AF18, {'Accepted Drops'!$AG$83:$AG$330,'Accepted Drops'!$AC$83:$AC$330}, 2, 0),0))} -> 36486338 | O18: Tormented Demons - Tormented Synapse | P18: Scurrius - Scurrius' Spine
A19: JaysunMimosa | E19: ✅ | F19: ✅ | L19: {=SUM(IF( 'Individual Stats'!O19:AW19="", 0, IFERROR( VLOOKUP( 'Individual Stats'!O19:AW19, 'Accepted Drops'!$B$84:$R$328, 17, FALSE ), 0 ) ))} -> 24.416667 | M19: =COUNTA(O19:AM19) -> 7 | N19: {=SUM(IFERROR(VLOOKUP('Tradeable Drops'!B19:AF19, {'Accepted Drops'!$AG$83:$AG$330,'Accepted Drops'!$AC$83:$AC$330}, 2, 0),0))} -> 64994854 | O19: Tombs of Amascut - Masori Piece (any) | P19: GOTR - Catalytic Talisman | Q19: GOTR - Abyssal Lantern | R19: DT2 Bosses - Chromium Ingot | S19: Hueycoatl - Tome of Earth | T19: Royal Titans - Mystic Vigour Prayer Scroll | U19: Zalcano - Crystal Tool Seed
A20: Lowbob PVM | E20: ✅ | L20: {=SUM(IF( 'Individual Stats'!O20:AW20="", 0, IFERROR( VLOOKUP( 'Individual Stats'!O20:AW20, 'Accepted Drops'!$B$84:$R$328, 17, FALSE ), 0 ) ))} -> 24 | M20: =COUNTA(O20:AM20) -> 6 | N20: {=SUM(IFERROR(VLOOKUP('Tradeable Drops'!B20:AF20, {'Accepted Drops'!$AG$83:$AG$330,'Accepted Drops'!$AC$83:$AC$330}, 2, 0),0))} -> 19961031 | O20: Araxxor - Noxious Piece (any) | P20: Abyssal Sire - Unsired | Q20: Alchemical Hydra - Jar of Chemicals | R20: Jar/Pet - Jar | S20: Cerberus - Eternal Crystal | T20: Cerberus - Smouldering Stone
A21: Mandahore | F21: ✅ | L21: {=SUM(IF( 'Individual Stats'!O21:AW21="", 0, IFERROR( VLOOKUP( 'Individual Stats'!O21:AW21, 'Accepted Drops'!$B$84:$R$328, 17, FALSE ), 0 ) ))} -> 0 | M21: =COUNTA(O21:AM21) -> 0 | N21: {=SUM(IFERROR(VLOOKUP('Tradeable Drops'!B21:AF21, {'Accepted Drops'!$AG$83:$AG$330,'Accepted Drops'!$AC$83:$AC$330}, 2, 0),0))} -> 0
A22: MiaTheDuck3 | B22: ✅ | C22: ✅ | D22: ✅ | E22: ✅ | F22: ✅ | I22: ✅ | J22: ✅ | K22: ✅ | L22: {=SUM(IF( 'Individual Stats'!O22:AW22="", 0, IFERROR( VLOOKUP( 'Individual Stats'!O22:AW22, 'Accepted Drops'!$B$84:$R$328, 17, FALSE ), 0 ) ))} -> 5.125 | M22: =COUNTA(O22:AM22) -> 6 | N22: {=SUM(IFERROR(VLOOKUP('Tradeable Drops'!B22:AF22, {'Accepted Drops'!$AG$83:$AG$330,'Accepted Drops'!$AC$83:$AC$330}, 2, 0),0))} -> 1408462 | O22: Mortimer - Leaf-bladed Sword | P22: Mortimer - Leaf-bladed Sword | Q22: Mortimer - Leaf-bladed Sword | R22: Moons of Peril - Blue Moon Piece (any) | S22: Scurrius - Scurrius' Spine | T22: Wilderness Trio - Dragon Pickaxe
A23: OdinswrathUN | L23: {=SUM(IF( 'Individual Stats'!O23:AW23="", 0, IFERROR( VLOOKUP( 'Individual Stats'!O23:AW23, 'Accepted Drops'!$B$84:$R$328, 17, FALSE ), 0 ) ))} -> 5 | M23: =COUNTA(O23:AM23) -> 4 | N23: {=SUM(IFERROR(VLOOKUP('Tradeable Drops'!B23:AF23, {'Accepted Drops'!$AG$83:$AG$330,'Accepted Drops'!$AC$83:$AC$330}, 2, 0),0))} -> 203276 | O23: Vorkath - Vorkath's Head | P23: Grotesque Guardians - Granite Ring | Q23: Grotesque Guardians - Granite Maul | R23: Grotesque Guardians - Granite Maul
A24: Papi Aksta | F24: ✅ | L24: {=SUM(IF( 'Individual Stats'!O24:AW24="", 0, IFERROR( VLOOKUP( 'Individual Stats'!O24:AW24, 'Accepted Drops'!$B$84:$R$328, 17, FALSE ), 0 ) ))} -> 32.222222 | M24: =COUNTA(O24:AM24) -> 8 | N24: {=SUM(IFERROR(VLOOKUP('Tradeable Drops'!B24:AF24, {'Accepted Drops'!$AG$83:$AG$330,'Accepted Drops'!$AC$83:$AC$330}, 2, 0),0))} -> 133328092 | O24: Thieving - Blood Shard | P24: Thieving - Enhanced Crystal Teleport Seed | Q24: Doom of Mokhaiotl - Eye of Ayak | R24: God Wars Dungeon - Armadyl Crossbow | S24: God Wars Dungeon - Bandos Hilt | T24: God Wars Dungeon - Bandos Piece (any) | U24: God Wars Dungeon - Godsword Shard (any) | V24: Yama - Soulflame Horn
A25: Pavlovs dog | B25: ✅ | C25: ✅ | D25: ✅ | E25: ✅ | F25: ✅ | I25: ✅ | J25: ✅ | K25: ✅ | L25: {=SUM(IF( 'Individual Stats'!O25:AW25="", 0, IFERROR( VLOOKUP( 'Individual Stats'!O25:AW25, 'Accepted Drops'!$B$84:$R$328, 17, FALSE ), 0 ) ))} -> 22.416667 | M25: =COUNTA(O25:AM25) -> 17 | N25: {=SUM(IFERROR(VLOOKUP('Tradeable Drops'!B25:AF25, {'Accepted Drops'!$AG$83:$AG$330,'Accepted Drops'!$AC$83:$AC$330}, 2, 0),0))} -> 197152349 | O25: Barrows - Ahrim's Piece (any) | P25: Barrows - Dharok's Piece (any) | Q25: Barrows - Verac's Piece (any) | R25: Barrows - Dharok's Piece (any) | S25: Barrows - Torag's Piece (any) | T25: Barrows - Karil's Piece (any) | U25: Barrows - Karil's Piece (any) | V25: Barrows - Verac's Piece (any) | W25: Tormented Demons - Tormented Synapse | X25: Barrows - Torag's Piece (any) | Y25: Scurrius - Scurrius' Spine | Z25: Scurrius - Scurrius' Spine | AA25: Scurrius - Scurrius' Spine | AB25: Gauntlet - Crystal Weapon Seed | AC25: DT2 Bosses - Virtus Piece (any) | AD25: Gauntlet - Enhanced Crystal Weapon Seed | AE25: Royal Titans - Ice Element Staff Crown
A26: Rs Kill King | L26: {=SUM(IF( 'Individual Stats'!O26:AW26="", 0, IFERROR( VLOOKUP( 'Individual Stats'!O26:AW26, 'Accepted Drops'!$B$84:$R$328, 17, FALSE ), 0 ) ))} -> 3 | M26: =COUNTA(O26:AM26) -> 4 | N26: {=SUM(IFERROR(VLOOKUP('Tradeable Drops'!B26:AF26, {'Accepted Drops'!$AG$83:$AG$330,'Accepted Drops'!$AC$83:$AC$330}, 2, 0),0))} -> 9056479 | O26: Dagannoth Kings - Seercull | P26: Dagannoth Kings - Rings (other) | Q26: Fortis Colosseum - Sunfire fanatic chausses | R26: Fortis Colosseum - Echo crystal(s) (1-3)
A27: sfsd | D27: ✅ | L27: {=SUM(IF( 'Individual Stats'!O27:AW27="", 0, IFERROR( VLOOKUP( 'Individual Stats'!O27:AW27, 'Accepted Drops'!$B$84:$R$328, 17, FALSE ), 0 ) ))} -> 9.3888889 | M27: =COUNTA(O27:AM27) -> 5 | N27: {=SUM(IFERROR(VLOOKUP('Tradeable Drops'!B27:AF27, {'Accepted Drops'!$AG$83:$AG$330,'Accepted Drops'!$AC$83:$AC$330}, 2, 0),0))} -> 22594188 | O27: Cerberus - Eternal Crystal | P27: Zulrah - Tanzanite Fang | Q27: Zulrah - Uncut Onyx | R27: God Wars Dungeon - Staff of the Dead | S27: Royal Titans - Ice Element Staff Crown
A28: ShermyX | B28: ✅ | C28: ✅ | D28: ✅ | E28: ✅ | L28: {=SUM(IF( 'Individual Stats'!O28:AW28="", 0, IFERROR( VLOOKUP( 'Individual Stats'!O28:AW28, 'Accepted Drops'!$B$84:$R$328, 17, FALSE ), 0 ) ))} -> 16 | M28: =COUNTA(O28:AM28) -> 12 | N28: {=SUM(IFERROR(VLOOKUP('Tradeable Drops'!B28:AF28, {'Accepted Drops'!$AG$83:$AG$330,'Accepted Drops'!$AC$83:$AC$330}, 2, 0),0))} -> 2840383 | O28: Tempoross - Soaked Pages X 25 | P28: Tempoross - Tome of Water | Q28: Tempoross - Soaked Pages X 25 | R28: Tempoross - Soaked Pages X 25 | S28: Tempoross - Soaked Pages X 25 | T28: Tempoross - Soaked Pages X 25 | U28: Tempoross - Soaked Pages X 25 | V28: Tempoross - Soaked Pages X 25 | W28: Tempoross - Soaked Pages X 25 | X28: Wintertodt - Tome of Fire | Y28: GOTR - Abyssal Lantern | Z28: GOTR - Elemental Talisman
